#VRML_SIM R2020b utf8
WorldInfo {
  coordinateSystem "NUE"
}
Viewpoint {
  orientation -0.07689761053582195 -0.9947262528579701 -0.06787075488767354 1.4514984440401042
  position -10.929849430640946 1.4988239926797788 2.5570314784133648
}
TexturedBackground {
}
TexturedBackgroundLight {
}
RectangleArena {
  floorSize 10 10
}
Robot {
  translation -2.9003257405302895e-07 0.0821466432242669 -5.796146372280464e-13
  rotation -2.1381191572311983e-06 -9.533766105630796e-06 0.9999999999522678 2.3056003032458183e-08
  children [
    Solid {
      translation 0 0.0635 0
      rotation 0.9020651059950672 5.26733434647014e-06 0.4315999820648319 7.072420838054932e-19
      children [
        Gyro {
        }
        Hinge2Joint {
          jointParameters HingeJointParameters {
            position 7.660075906891375e-16
            axis 0 1 0
            anchor 0.152 -0.0885 0.162
          }
          jointParameters2 JointParameters {
            position 5.965373526639451e-16
            axis 1 0 0
          }
          device [
            RotationalMotor {
              name "Talon SRX[10]"
            }
            PositionSensor {
              name "Talon SRX[10] Encoder"
            }
          ]
          device2 [
            RotationalMotor {
              name "Talon SRX[14]"
            }
          ]
          endPoint Solid {
            translation 0.15159999999999998 -0.0884999999999998 0.16200000000000003
            rotation 0.5773506025225384 -0.5773506025225372 0.5773496025232243 2.094399999999999
            children [
              DEF Wheel Shape {
                appearance PBRAppearance {
                }
                geometry Cylinder {
                  height 0.015
                  radius 0.0635
                }
              }
            ]
            name "BR Wheel"
            boundingObject USE Wheel
            physics Physics {
            }
            linearVelocity -6.578999227874073e-10 0.00015998951739968286 -1.6889945711675792e-15
            angularVelocity -2.6694083292893926e-14 -1.693006031583398e-15 -5.209614012253196e-08
          }
        }
        Hinge2Joint {
          jointParameters HingeJointParameters {
            position 8.972879477305434e-16
            axis 0 1 0
            anchor -0.152 -0.0885 0.162
          }
          jointParameters2 JointParameters {
            position 8.369115161402117e-16
            axis 1 0 0
          }
          device [
            RotationalMotor {
              name "Talon SRX[5]"
            }
            PositionSensor {
              name "Talon SRX[5] Encoder"
            }
          ]
          device2 [
            RotationalMotor {
              name "Talon SRX[1]"
            }
          ]
          endPoint Solid {
            translation -0.15159999999999996 -0.0884999999999998 0.16200000000000003
            rotation 0.5773506025218 -0.5773506025217974 0.5773496025247027 2.09439999999778
            children [
              DEF Wheel Shape {
                appearance PBRAppearance {
                }
                geometry Cylinder {
                  height 0.015
                  radius 0.0635
                }
              }
            ]
            name "BL Wheel"
            boundingObject USE Wheel
            physics Physics {
            }
            linearVelocity -8.248643215037369e-10 0.00015998617567194177 -1.6491021308696073e-15
            angularVelocity -2.5964160691378472e-14 7.943973396159075e-17 7.545519902252238e-08
          }
        }
        Hinge2Joint {
          jointParameters HingeJointParameters {
            position -3.068803974660971e-16
            axis 0 1 0
            anchor -0.152 -0.0885 -0.162
          }
          jointParameters2 JointParameters {
            position -3.1260416052573303e-16
            axis 1 0 0
          }
          device [
            RotationalMotor {
              name "Talon SRX[4]"
            }
            PositionSensor {
              name "Talon SRX[4] Encoder"
            }
          ]
          device2 [
            RotationalMotor {
              name "Talon SRX[0]"
            }
          ]
          endPoint Solid {
            translation -0.15159999999999996 -0.0884999999999998 -0.16199999999999998
            rotation 0.577350602518522 -0.5773506025185231 0.5773496025312549 2.0943999999879552
            children [
              DEF Wheel Shape {
                appearance PBRAppearance {
                }
                geometry Cylinder {
                  height 0.015
                  radius 0.0635
                }
              }
            ]
            name "FL Wheel"
            boundingObject USE Wheel
            physics Physics {
            }
            linearVelocity -8.248648144450518e-10 0.00015998617565040282 -1.7094008544763768e-15
            angularVelocity -2.7446885529577536e-14 -7.161620817882027e-16 7.545520812690777e-08
          }
        }
        Hinge2Joint {
          jointParameters HingeJointParameters {
            position 8.799826139268128e-16
            axis 0 1 0
            anchor 0.152 -0.0885 -0.162
          }
          jointParameters2 JointParameters {
            position 6.625932170555708e-16
            axis 1 0 0
          }
          device [
            RotationalMotor {
              name "Talon SRX[11]"
            }
            PositionSensor {
              name "Talon SRX[11] Encoder"
            }
          ]
          device2 [
            RotationalMotor {
              name "Talon SRX[15]"
            }
          ]
          endPoint Solid {
            translation 0.15159999999999998 -0.0884999999999998 -0.16199999999999998
            rotation 0.577350602522538 -0.5773506025225372 0.5773496025232249 2.094399999999999
            children [
              DEF Wheel Shape {
                appearance PBRAppearance {
                }
                geometry Cylinder {
                  height 0.015
                  radius 0.0635
                }
              }
            ]
            name "FR Wheel"
            boundingObject USE Wheel
            physics Physics {
            }
            linearVelocity -6.578986026413593e-10 0.00015998951740087952 -1.7589509796193824e-15
            angularVelocity -2.6819679336431528e-14 -2.3411115883185497e-15 -5.2096194748825176e-08
          }
        }
        DEF Base Shape {
          appearance PBRAppearance {
            metalness 0.1
          }
          geometry Box {
            size 0.46101 0.05 0.45085
          }
        }
      ]
      boundingObject USE Base
      physics Physics {
      }
    }
  ]
  boundingObject Box {
    size 0.461 0.177 0.451
  }
  physics Physics {
  }
  controller "DeepBlueSim"
  supervisor TRUE
  linearVelocity -1.1965321382447236e-09 5.374075625930701e-07 -2.6923888511518456e-15
  angularVelocity -2.6310241126612047e-14 7.585112080475777e-17 1.165912997985458e-08
}
