#VRML_SIM R2020b utf8
WorldInfo {
  coordinateSystem "NUE"
}
Viewpoint {
  orientation -0.07689761053582195 -0.9947262528579701 -0.06787075488767354 1.4514984440401042
  position -10.929849430640946 1.4988239926797788 2.5570314784133648
}
TexturedBackground {
}
TexturedBackgroundLight {
}
RectangleArena {
  floorSize 10 10
}
Robot {
  translation -2.894916276704967e-07 0.08214669637323631 -5.785019634611125e-13
  rotation -2.1761642965144473e-06 -1.2970602081855947e-05 0.999999999913514 1.6935858487425998e-08
  children [
    Solid {
      translation 0 0.0635 0
      rotation 0.9020651059950672 5.26733434647014e-06 0.4315999820648319 7.072420838054932e-19
      children [
        Gyro {
        }
        Hinge2Joint {
          jointParameters HingeJointParameters {
            position 9.527359555946845e-16
            axis 0 1 0
            anchor 0.152 -0.0885 0.162
          }
          jointParameters2 JointParameters {
            position 7.949251744051113e-16
            axis 1 0 0
          }
          device [
            RotationalMotor {
              name "Talon SRX[10]"
              maxVelocity 7.861
            }
            PositionSensor {
              name "Talon SRX[10] Encoder"
            }
          ]
          device2 [
            RotationalMotor {
              name "Talon SRX[14]"
              maxVelocity 83.681
            }
          ]
          endPoint Solid {
            translation 0.15159999999999998 -0.0884999999999998 0.16200000000000003
            rotation 0.577350602522539 -0.5773506025225372 0.5773496025232239 2.094399999999999
            children [
              DEF Wheel Shape {
                appearance PBRAppearance {
                }
                geometry Cylinder {
                  height 0.015
                  radius 0.0635
                }
              }
            ]
            name "BR Wheel"
            boundingObject USE Wheel
            physics Physics {
            }
            linearVelocity -7.363111055124708e-10 7.51206405235167e-07 -4.7339524494781067e-17
            angularVelocity 1.0318738780555115e-16 -1.7363061814725735e-15 -3.849970119972266e-10
          }
        }
        Hinge2Joint {
          jointParameters HingeJointParameters {
            position 1.011031921364176e-15
            axis 0 1 0
            anchor -0.152 -0.0885 0.162
          }
          jointParameters2 JointParameters {
            position 1.0146630741874214e-15
            axis 1 0 0
          }
          device [
            RotationalMotor {
              name "Talon SRX[5]"
              maxVelocity 7.861
            }
            PositionSensor {
              name "Talon SRX[5] Encoder"
            }
          ]
          device2 [
            RotationalMotor {
              name "Talon SRX[1]"
              maxVelocity 83.681
            }
          ]
          endPoint Solid {
            translation -0.15159999999999996 -0.0884999999999998 0.16200000000000003
            rotation 0.5773506025218006 -0.5773506025217974 0.5773496025247021 2.09439999999778
            children [
              DEF Wheel Shape {
                appearance PBRAppearance {
                }
                geometry Cylinder {
                  height 0.015
                  radius 0.0635
                }
              }
            ]
            name "BL Wheel"
            boundingObject USE Wheel
            physics Physics {
            }
            linearVelocity 7.41056474906453e-10 7.512182492527695e-07 -1.4324775819561678e-17
            angularVelocity -7.388089653881007e-16 -1.0098494669302477e-15 3.1119688952031406e-10
          }
        }
        Hinge2Joint {
          jointParameters HingeJointParameters {
            position -2.859767727092677e-16
            axis 0 1 0
            anchor -0.152 -0.0885 -0.162
          }
          jointParameters2 JointParameters {
            position -3.1260416052573303e-16
            axis 1 0 0
          }
          device [
            RotationalMotor {
              name "Talon SRX[4]"
              maxVelocity 7.861
            }
            PositionSensor {
              name "Talon SRX[4] Encoder"
            }
          ]
          device2 [
            RotationalMotor {
              name "Talon SRX[0]"
              maxVelocity 83.681
            }
          ]
          endPoint Solid {
            translation -0.15159999999999996 -0.0884999999999998 -0.16199999999999998
            rotation 0.5773506025185219 -0.5773506025185232 0.5773496025312552 2.0943999999879552
            children [
              DEF Wheel Shape {
                appearance PBRAppearance {
                }
                geometry Cylinder {
                  height 0.015
                  radius 0.0635
                }
              }
            ]
            name "FL Wheel"
            boundingObject USE Wheel
            physics Physics {
            }
            linearVelocity 7.410571952516961e-10 7.512182432698601e-07 3.926163640487117e-17
            angularVelocity 4.507785462133202e-16 -8.205390802369612e-17 3.111786807531683e-10
          }
        }
        Hinge2Joint {
          jointParameters HingeJointParameters {
            position 9.612516204848671e-16
            axis 0 1 0
            anchor 0.152 -0.0885 -0.162
          }
          jointParameters2 JointParameters {
            position 9.16486260797364e-16
            axis 1 0 0
          }
          device [
            RotationalMotor {
              name "Talon SRX[11]"
              maxVelocity 7.861
            }
            PositionSensor {
              name "Talon SRX[11] Encoder"
            }
          ]
          device2 [
            RotationalMotor {
              name "Talon SRX[15]"
              maxVelocity 83.681
            }
          ]
          endPoint Solid {
            translation 0.15159999999999998 -0.0884999999999998 -0.16199999999999998
            rotation 0.5773506025225384 -0.5773506025225372 0.5773496025232243 2.094399999999999
            children [
              DEF Wheel Shape {
                appearance PBRAppearance {
                }
                geometry Cylinder {
                  height 0.015
                  radius 0.0635
                }
              }
            ]
            name "FR Wheel"
            boundingObject USE Wheel
            physics Physics {
            }
            linearVelocity -7.363115503373466e-10 7.512063884828208e-07 5.146912611827698e-19
            angularVelocity -7.460460954672844e-17 -6.748498078671771e-16 -3.8501522076130383e-10
          }
        }
        DEF Base Shape {
          appearance PBRAppearance {
            metalness 0.1
          }
          geometry Box {
            size 0.46101 0.05 0.45085
          }
        }
      ]
      boundingObject USE Base
      physics Physics {
      }
    }
  ]
  boundingObject Box {
    size 0.461 0.177 0.451
  }
  physics Physics {
  }
  controller "DeepBlueSim"
  supervisor TRUE
  linearVelocity 3.7368335661081186e-12 -1.7488942333785176e-09 6.474937208706458e-17
  angularVelocity 9.291012494429457e-16 1.295205774328766e-16 -3.700159532317513e-11
}
